Workbook

Sheet Planning
B1: MS1 | D1: MS2 | F1: MS3 | H1: MS4 | J1: MS5 | L1: MS6 | N1: MS7 | P1: MS8 | R1: MS9 | T1: MS11 | V1: MS12 | X1: MS13 | Z1: MS14
B2: Concept | D2: Prepro1-PoC | F2: Prepro2 - VS1 | H2: Prepro3- VS2 | J2: PROD1 | L2: PROD2 | N2: PROD3 | P2: PROD4 | R2: PROD5 | T2: ALPHA | V2: Ext QA | X2: SUBMISSION | Z2: PATCH
A3: Sprints de 2 semanas | B3: Sprint1 | C3: Sprint2 | D3: Sprint3 | E3: Sprint4 | F3: Sprint5 | G3: Sprint6 | H3: Sprint7 | I3: Sprint8 | J3: Sprint9 | K3: Sprint10 | L3: Sprint11 | M3: Sprint12 | N3: Sprint13 | O3: Sprint14 | P3: Sprint15 | Q3: Sprint16 | R3: Sprint17 | S3: Sprint18 | T3: Sprint19 | U3: Sprint20 | V3: Sprint21 | W3: Sprint22 | X3: Sprint23 | Y3: Sprint24 | Z3: Sprint25
A4: Nombre MS | X4: Submission1 | Y4: Submission2 | Z4: Parche
A5: ARTE
A6: Concept Artist1 | B6: Con.Jugador | C6: Con VS | D6: Con EN1+EN2 | E6: Con EN3+EN4 | F6: Ep1 CON | G6: Con Ep2 | H6: Con EN5+EN6 | I6: Con Ep3 | J6: Con EN7 | K6: Con Ep4 | L6: Con Ep5 | M6: Con Ep6 | N6: Con Ep7 | O6: vacaciones | P6: vacaciones | Q6: buffer
A7: Modelador1 | C7: Player | D7: Player, II | E7: Mod EN1 | F7: Mod EN2 | G7: Mod EN3 | H7: Mod EN4 | I7: Mod EN5 | J7: Mod EN6 | K7: Mod EN7 | L7: vacaciones | M7: vacaciones | N7: Marketing | O7: Marketing,II | P7: buffer | Q7: <-- | R7: <-- | S7: <-- | T7: polish/bug fixing | U7: polish/bug fixing | V7: support | W7: <-- | X7: <-- | Y7: <-- | Z7: <--
A8: Animador1 | E8: Anm Player | F8: Anm EN1 | G8: Anm EN2 | H8: Anm EN3 | I8: Anm EN4 | J8: Anm EN5 | K8: Anm EN6 | L8: Anm EN7 | M8: vacaciones | N8: vacaciones | O8: buffer
A9: Extra ( solo si nec)
A10: DISEÑO
A11: Diseñador 1 | B11: gdd draft | C11: gdd final | D11: Metricas | E11: Playground | F11: Dis- Mec1 | G11: Ep1 FUN | H11: Dis- Mec2 | I11: Dis- Mec3 | J11: Dis- Mec5 | K11: Dis- Mec6 | L11: Dis Puzzle2 | M11: Dis Puzzle3 | N11: Dis Puzzle4 | O11: Play-testing | P11: Vacaciones | Q11: Vacaciones | R11: buffer | S11: buffer | T11: polish/bug fixing | U11: polish/bug fixing | V11: support | W11: <-- | X11: <-- | Y11: <-- | Z11: <--
A12: Diseñador 2 | E12: VS Fun | F12: script draft | G12: script final | H12: Ep2 FUN | I12: Dis- Mec4 | J12: Ep3 FUN | K12: Dis Puzzle1 | L12: Ep4 FUN | M12: Ep5 FUN | N12: Ep6 FUN | O12: Ep7 FUN | P12: Play-testing | Q12: Vacaciones | R12: Vacaciones | S12: buffer | T12: polish/bug fixing | U12: polish/bug fixing
A13: Extra ( solo si nec)
A14: CODE
A15: Coder1 | E15: Camara | F15: MecVS | G15: Mec1 | H15: Vacaciones | I15: Vacaciones | J15: Mec2 | K15: Mec3 | L15: Mec4 | M15: Mec5 | N15: Mec6 | O15: Puzz1 | P15: Puzz2 | Q15: Puzz3 | R15: Xbox XR | S15: buffer | T15: polish/bug fixing | U15: polish/bug fixing | V15: support | W15: <-- | X15: <-- | Y15: <-- | Z15: <--
A16: Extra ( solo si nec) | Q16: Puzz4 | R16: PS4 TRC | S16: buffer | T16: polish/bug fixing | U16: polish/bug fixing
A17: LEVEL
A18: Level Artist1 | F18: VS Par | G18: VS POL | H18: Ep1 PAR | I18: Ep2 PAR | J18: Ep1 POL | K18: Ep3 PAR | L18: Ep2 POL | M18: Ep4 PAR | N18: Vacaciones | O18: Vacaciones | P18: Ep5 PAR | Q18: Ep6 PAR | R18: Ep7 PAR | S18: buffer | T18: polish/bug fixing | U18: polish/bug fixing | V18: support | W18: <-- | X18: <-- | Y18: <-- | Z18: <--
A19: Extra ( solo si nec) | N19: Ep3 POL | O19: Ep4 POL | P19: Ep5 POL | Q19: Ep6 POL | R19: Ep7 POL | S19: buffer | T19: polish/bug fixing | U19: polish/bug fixing
A20: Depts varios
A21: Sonido | J21: VS SONO | K21: Ep1 Sono | L21: Ep2 Sono | M21: Ep3 Sono | N21: Ep4 Sono | O21: Vacaciones | P21: Ep5 Sono | Q21: Ep6 Sono | R21: Ep7 Sono | S21: buffer | T21: polish/bug fixing | U21: polish/bug fixing | V21: support | W21: <-- | X21: <-- | Y21: <-- | Z21: <--
A22: VFX | J22: VS VFX | K22: Ep1 Vfx | L22: Ep2 Vfx | M22: Ep3 Vfx | N22: Ep4 Vfx | O22: Vacaciones | P22: Ep5 Vfx | Q22: Ep6 Vfx | R22: Ep7 Vfx | S22: buffer | T22: polish/bug fixing | U22: polish/bug fixing | V22: support | W22: <-- | X22: <-- | Y22: <-- | Z22: <--
B26: DISEÑO | D26: gdd draft | E26: 2 semanas | F26: Ya puesto | J26: gdd draft
D27: gdd final | E27: 2 semanas | F27: Ya puesto | J27: gdd final
D28: script draft | E28: 2 semanas | F28: Ya puesto | J28: script draft
D29: script final | E29: 2 semanas | F29: Ya puesto | J29: script final
D30: Mecanica"X" | E30: 2 semanas | F30: (tantas como mecanicas) | H30: Ya puesto | J30: Dis- Mec1 | K30: Dis- Mec2 | L30: Dis- Mec3 | M30: Dis- Mec4 | O30: NOTA: Numero según tirada dado virtual
D31: Metricas | E31: 2 semanas | F31: Ya puesto | J31: Metricas
D32: Playground | E32: 2 semanas | F32: Ya puesto | J32: Playground
D33: Puzzle"P" | E33: 2 semanas | F33: (tantas como puzles) | H33: Ya puesto | J33: Dis Puzzle1 | K33: Dis Puzzle2 | L33: Dis Puzzle3
D34: VS Fun | E34: 2 semanas | F34: Ya puesto | J34: VS Fun
D35: Ep"L" Fun | E35: 2 semanas | F35: (Episodios en estado funcional) ( tantas como episodios) | I35: Ya puesto | J35: Ep1 FUN | K35: Ep2 FUN | L35: Ep3 FUN | M35: Ep4 FUN | N35: Ep5 FUN | O35: Ep6 FUN | Q35: NOTA: Numero según tirada dado virtual
B37: ARTE | C37: Concept | D37: Con.Jugador | E37: 2 semanas | F37: Ya puesto | J37: Con.Player
D38: Con.En"CE" | E38: 1 semana | F38: (Concept de enemigos) (Tantos como enemigos) | I38: Ya puesto | J38: Con EN1+EN2 | L38: Con EN3+EN4 | N38: Con EN5+EN6 | P38: Con EN7+EN8
D39: Con VS | E39: 1semanas | F39: Ya puesto | J39: Con VS
D40: Con.Ep"CL" | E40: 2 semana | F40: (Concept de niveles) (Tantos como niveles) | J40: Con Ep1 | K40: Con Ep2 | L40: Con Ep3 | M40: Con Ep4 | N40: Con Ep5 | O40: Con Ep6 | Q40: NOTA: Numero según tirada dado virtual
D41: Marketing | E41: 4 semanas | J41: Marketing | K41: Marketing,II
C42: Modelado | D42: Player | E42: 4 semanas | F42: Ya puesto | J42: Player | K42: Player,II
D43: Enemigos"ME" | E43: 2 semanas | F43: (Modelado de enemigos) (Tantos como enemigos) | I43: Ya puesto | J43: Mod EN1 | K43: Mod EN2 | L43: Mod EN3 | M43: Mod EN4 | N43: Mod EN5 | O43: Mod EN6 | P43: Mod EN7 | Q43: Mod EN8
C44: Animacion | D44: Anm Player | E44: 2 semanas | F44: Ya puesto | J44: Anm Player
...

Sheet Dados Virtuales
A1: PLANNING | D1: RESULTADO | E1: Variabilidad
A2: Mecanicas | B2: 43868 | C2: 1+1d6 | D2: 6 | E2: 6
A3: Puzzle | B3: 43834 | C3: 1d4 | D3: 4 | E3: 4
A4: Episodios | B4: 43898 | C4: 2+1d6 | D4: 7 | E4: 6
A5: Enemigos | B5: 43931 | C5: 2+2d4 | D5: 7 | E5: 16
E6: =E2*E3*E4*E5 -> 2304
AI8: EoL
C12: RELLENAR POR ALUMNO

Sheet Dependencias
A1: TAREAS y DEPENDENCIAS
A2: Departamento | B2: Tarea(s) y Flujo | C2: Dependecias
A3: ARTE | E3: Con EN1+EN2 | F3: Mod EN1 | G3: Anm EN1
A4: Concept | B4: Con.Jugador | C4: DESBLOQUEA: Necesario tenerlo antes de modelarlo | D4: listo
B5: Con.EnX- Concept enemigo | C5: DESBLOQUEA: Modelado enemigo | D5: listo
B6: Con.VS y Con. EpX | C6: DESBLOQUEA: Poder hacer nivel en PAR y POL ( no influye para FUN) | D6: listo | E6: arte
A7: MODELADO | E7: Con Ep1 | F7: Ep1 PAR | G7: Ep1 POL
A8: Personajes | B8: Modelado de enemigo/jugador requiere de concepto previo | C8: (Modelado se asume que incluye rigging y texturizado) | D8: listo | G8: Ep1 Sono
A9: Animacion | G9: Ep1 Vfx
A10: JUGADOR | B10: Puesta ya en plantila | D10: listo
A11: Personajes | B11: Animacion de enemigos requiere de modelado | C11: Requiere modelado | D11: listo
A12: NIVELES | B12: Aletermativamente, se puede crear uan tarea para el jugadoir de misma duracion entiempo que las de enemigos
A13: NIVELES | B13: ParStandard -> Polish/Pulido | C13: Requiere de nivel en FUN ( Funcional o BlockOut ) por parte de diseño
C14: 2 semanas cada estado de nivel: 2 para PAR , 2 para POL...
A15: DISEÑO
B16: Guion/Script | C16: Requiere de GDD terminado | D16: listo
B17: Mecanicas | C17: Requiere de GDD terminado | D17: listo
B18: Metricas | C18: Requiere de todas las mecanicas | D18: listo
B19: Puzzles | C19: NO los necesitamos para desbloquear PlayGround ( se pueden ir añadiendo) | D19: listo
B20: PlayGround | C20: Requiere Metricas ( pero no de Puzzles) | D20: listo
B21: Ajustes por play testing | C21: Tras realizar produccion un playtesting (OPCIONAL)
A22: SONIDO
B23: Musica : se considera externa y no se tiene en cuenta en planificacion
B24: Episodio Sonido | C24: Requiere que mapa este al menor terminado en PAR
A25: VFX
B26: Episodio VFX | C26: Requiere que mapa este al menos terminado en PAR. Recomendado simultaneo con sono
A27: PROGR+A53
B28: Mec | C28: Requiere que diseño haya terminado su trabajo de esa mecanica antes
B29: Puzzle | C29: Idem
A30: CINEMATICAS | B30: NO HAY EN ESTE EJEMPLO
A33: Meter vacaciones según correspondan!!!

Sheet Disclaimer
A1: Por mejorar si fuera real...
A2: ( para que lo tengais encuenta si usais esta plantilla en el futuro)
A4: ARTE: Habria que meter marketing: posters, y trailer / Teaser a tiempo
A5: TODOS: Posible demo para decargar y generar traccion de usuarios
A7: CINEMATICAS: Este es un juego sin cinematicas, por eso no hay departamento como tal

Sheet Presupuesto
A1: He asumido que los trabajadores que trabajan medio mes cobran por mes entero
B2: Presupuesto
B3: MS1 | D3: MS2 | F3: MS3 | H3: MS4 | J3: MS5 | L3: MS6 | N3: MS7 | P3: MS8 | R3: MS9 | T3: MS11 | V3: MS12 | X3: MS13 | Z3: MS14
B4: Concept | D4: Prepro1-PoC | F4: Prepro2 - VS1 | H4: Prepro3- VS2 | J4: PROD1 | L4: PROD2 | N4: PROD3 | P4: PROD4 | R4: PROD5 | T4: ALPHA | V4: Ext QA | X4: SUBMISSION | Z4: PATCH
A5: cada mes | B5: =ROUNDUP((COUNTA(Planning!B6:C22)/2),0)*3000 -> 9000 | D5: =ROUNDUP((COUNTA(Planning!D6:E22)/2),0)*3000 -> 15000 | F5: =ROUNDUP((COUNTA(Planning!F6:G22)/2),0)*3000 -> 21000 | H5: =ROUNDUP((COUNTA(Planning!H6:I22)/2),0)*3000 -> 21000 | J5: =ROUNDUP((COUNTA(Planning!J6:K22)/2),0)*3000 -> 27000 | L5: =ROUNDUP((COUNTA(Planning!L6:M22)/2),0)*3000 -> 27000 | N5: =ROUNDUP((COUNTA(Planning!N6:O22)/2),0)*3000 -> 30000 | P5: =ROUNDUP((COUNTA(Planning!P6:Q22)/2),0)*3000 -> 30000 | R5: =ROUNDUP((COUNTA(Planning!R6:S22)/2),0)*3000 -> 27000 | T5: =ROUNDUP((COUNTA(Planning!T6:U22)/2),0)*3000 -> 27000 | V5: =ROUNDUP((COUNTA(Planning!V6:W22)/2),0)*3000 -> 18000 | X5: =ROUNDUP((COUNTA(Planning!X6:Y22)/2),0)*3000 -> 18000 | Z5: =ROUNDUP((COUNTA(Planning!Z6:AA22)),0)*3000 -> 18000
A6: cada fase | B6: =SUM(B5:C5) -> 9000 | D6: =SUM(D5:I5) -> 57000 | J6: =SUM(J5:S5) -> 141000 | T6: =SUM(T5:U5) -> 27000 | V6: =SUM(V5:W5) -> 18000 | X6: =SUM(X5:Y5) -> 18000 | Z6: =SUM(Z5) -> 18000
A7: total | B7: =SUM(B6:Z6) -> 288000

Sheet Break-even
A1: Precio salida | B1: 30
A2: Precio medio | B2: 20
A3: Impuestos | B3: 0.2
A4: Plataforma | B4: 0.3
A6: Royalty 1
A7: Porcentaje publisher | B7: 0.8
A8: Porcentaje propio | B8: 0.2
A9: pecio sin plataforma | B9: =B$2-(B$2*B$4) -> 14
A10: precio neto(sin impuestos) | B10: =B$9-(B$9*B$3) -> 11.2
A11: beneficio final mio | B11: =B10*B8 -> 2.24
A12: total de copias vendidas para recuperar inversion | B12: =Presupuesto!B$7/'Break-even'!B11 -> 128571.43
A14: Royalty 2
A15: Porcentaje publisher | B15: 0.6
A16: Porcentaje propio | B16: 0.4
A17: pecio sin plataforma | B17: =B$2-(B$2*B$4) -> 14
A18: precio neto(sin impuestos) | B18: =B$9-(B$9*B$3) -> 11.2
A19: beneficio final mio | B19: =B18*B16 -> 4.48
A20: total de copias vendidas para recuperar inversion | B20: =Presupuesto!B$7/'Break-even'!B19 -> 64285.714
A22: Royalty 3
A23: Porcentaje publisher | B23: 0.5
A24: Porcentaje propio | B24: 0.5
A25: pecio sin plataforma | B25: =B$2-(B$2*B$4) -> 14
A26: precio neto(sin impuestos) | B26: =B$9-(B$9*B$3) -> 11.2
A27: beneficio final mio | B27: =B26*B24 -> 5.6
A28: total de copias vendidas para recuperar inversion | B28: =Presupuesto!B$7/'Break-even'!B27 -> 51428.571
